#VRML_SIM R2023a utf8

EXTERNPROTO "https://raw.githubusercontent.com/cyberbotics/webots/R2023a/projects/robots/sphero/bb8/protos/BB-8.proto"
EXTERNPROTO "https://raw.githubusercontent.com/cyberbotics/webots/R2023a/projects/robots/softbank/nao/protos/Nao.proto"
EXTERNPROTO "https://raw.githubusercontent.com/cyberbotics/webots/R2023a/projects/objects/backgrounds/protos/TexturedBackground.proto"
EXTERNPROTO "https://raw.githubusercontent.com/cyberbotics/webots/R2023a/projects/objects/backgrounds/protos/TexturedBackgroundLight.proto"
EXTERNPROTO "https://raw.githubusercontent.com/cyberbotics/webots/R2023a/projects/robots/gctronic/e-puck/protos/E-puck.proto"
EXTERNPROTO "https://raw.githubusercontent.com/cyberbotics/webots/R2023a/projects/humans/pedestrian/protos/Pedestrian.proto"
EXTERNPROTO "https://raw.githubusercontent.com/cyberbotics/webots/R2023a/projects/objects/factory/containers/protos/WoodenBox.proto"

WorldInfo {
  basicTimeStep 16
  coordinateSystem "NUE"
}
Viewpoint {
  orientation 0.12579708905807363 0.7024560986467269 0.7005216069890601 3.7213315510712217
  position 11.88314835870727 6.2910212358673485 -10.251464283252023
  follow "rectangle arena"
}
TexturedBackground {
  luminosity 0
}
TexturedBackgroundLight {
  texture "music_hall"
  luminosity 0
}
Solid {
  translation 0.173504 0 0.307859
  rotation 1 0 0 -1.5707996938995747
  children [
    Solid {
      children [
        Shape {
          appearance PBRAppearance {
            baseColorMap ImageTexture {
              url [
                "https://raw.githubusercontent.com/cyberbotics/webots/R2023a/projects/appearances/protos/textures/parquetry/chequered_parquetry_base_color.jpg"
              ]
            }
            roughness 1
            roughnessMap ImageTexture {
              url [
                "https://raw.githubusercontent.com/cyberbotics/webots/R2023a/projects/appearances/protos/textures/parquetry/chequered_parquetry_roughness.jpg"
              ]
            }
            metalness 0
            normalMap ImageTexture {
              url [
                "https://raw.githubusercontent.com/cyberbotics/webots/R2023a/projects/appearances/protos/textures/parquetry/chequered_parquetry_normal.jpg"
              ]
            }
            occlusionMap ImageTexture {
              url [
                "https://raw.githubusercontent.com/cyberbotics/webots/R2023a/projects/appearances/protos/textures/parquetry/chequered_parquetry_occlusion.jpg"
              ]
            }
          }
          geometry IndexedFaceSet {
            coord Coordinate {
              point [
                -5 -5 0
                5 -5 0
                -5 5 0
                5 5 0
              ]
            }
            texCoord TextureCoordinate {
              point [
                0 0
                20 0
                0 20
                20 20
              ]
            }
            coordIndex [
              2, 0, 1, 3, -1
            ]
            texCoordIndex [
              2, 0, 1, 3, -1
            ]
          }
        }
      ]
      name "floor"
      model "floor"
      boundingObject Plane {
        size 10 10
      }
      locked TRUE
    }
    Solid {
      translation 5.005 0 0.05
      children [
        Shape {
          appearance PBRAppearance {
            baseColorMap ImageTexture {
              url [
                "https://raw.githubusercontent.com/cyberbotics/webots/R2023a/projects/appearances/protos/textures/brushed_aluminium/brushed_aluminium_base_color.jpg"
              ]
            }
            roughnessMap ImageTexture {
              url [
                "https://raw.githubusercontent.com/cyberbotics/webots/R2023a/projects/appearances/protos/textures/brushed_aluminium/brushed_aluminium_roughness.jpg"
              ]
            }
            normalMap ImageTexture {
              url [
                "https://raw.githubusercontent.com/cyberbotics/webots/R2023a/projects/appearances/protos/textures/brushed_aluminium/brushed_aluminium_normal.jpg"
              ]
            }
          }
          geometry IndexedFaceSet {
            coord Coordinate {
              point [
                -0.005 5 0.05
                0.005 5 0.05
                0.005 5 -0.05
                -0.005 5 -0.05
                -0.005 -5 -0.05
                0.005 -5 -0.05
                0.005 -5 0.05
                -0.005 -5 0.05
                -0.005 -5 0.05
                0.005 -5 0.05
                0.005 5 0.05
                -0.005 5 0.05
                0.005 -5 -0.05
                -0.005 -5 -0.05
                -0.005 5 -0.05
                0.005 5 -0.05
                -0.005 -5 -0.05
                -0.005 -5 0.05
                -0.005 5 0.05
                -0.005 5 -0.05
                0.005 -5 0.05
                0.005 -5 -0.05
                0.005 5 -0.05
                0.005 5 0.05
              ]
            }
            texCoord TextureCoordinate {
              point [
                0.001 0.01
                0 0.01
                0 0
                0.001 0
                0 0
                0.001 0
                0.001 0.01
                0 0.01
                0 0.001
                0 0
                1 0
                1 0.001
                0 0.001
                0 0
                1 0
                1 0.001
                1 0
                1 0.01
                0 0.01
                0 0
                0 0.01
                0 0
                1 0
                1 0.01
              ]
            }
            coordIndex [
              0, 1, 2, 3, -1, 4, 5, 6, 7, -1, 8, 9, 10, 11, -1, 12, 13, 14, 15, -1, 16, 17, 18, 19, -1, 20, 21, 22, 23, -1
            ]
            creaseAngle 1.5
          }
        }
      ]
      name "wall"
      model "box"
      boundingObject Box {
        size 0.01 10 0.1
      }
    }
    Solid {
      translation -5.005 0 0.05
      children [
        Shape {
          appearance PBRAppearance {
            baseColorMap ImageTexture {
              url [
                "https://raw.githubusercontent.com/cyberbotics/webots/R2023a/projects/appearances/protos/textures/brushed_aluminium/brushed_aluminium_base_color.jpg"
              ]
            }
            roughnessMap ImageTexture {
              url [
                "https://raw.githubusercontent.com/cyberbotics/webots/R2023a/projects/appearances/protos/textures/brushed_aluminium/brushed_aluminium_roughness.jpg"
              ]
            }
            normalMap ImageTexture {
              url [
                "https://raw.githubusercontent.com/cyberbotics/webots/R2023a/projects/appearances/protos/textures/brushed_aluminium/brushed_aluminium_normal.jpg"
              ]
            }
          }
          geometry IndexedFaceSet {
            coord Coordinate {
              point [
                -0.005 5 0.05
                0.005 5 0.05
                0.005 5 -0.05
                -0.005 5 -0.05
                -0.005 -5 -0.05
                0.005 -5 -0.05
                0.005 -5 0.05
                -0.005 -5 0.05
                -0.005 -5 0.05
                0.005 -5 0.05
                0.005 5 0.05
                -0.005 5 0.05
                0.005 -5 -0.05
                -0.005 -5 -0.05
                -0.005 5 -0.05
                0.005 5 -0.05
                -0.005 -5 -0.05
                -0.005 -5 0.05
                -0.005 5 0.05
                -0.005 5 -0.05
                0.005 -5 0.05
                0.005 -5 -0.05
                0.005 5 -0.05
                0.005 5 0.05
              ]
            }
            texCoord TextureCoordinate {
              point [
                0.001 0.01
                0 0.01
                0 0
                0.001 0
                0 0
                0.001 0
                0.001 0.01
                0 0.01
                0 0.001
                0 0
                1 0
                1 0.001
                0 0.001
                0 0
                1 0
                1 0.001
                1 0
                1 0.01
                0 0.01
                0 0
                0 0.01
                0 0
                1 0
                1 0.01
              ]
            }
            coordIndex [
              0, 1, 2, 3, -1, 4, 5, 6, 7, -1, 8, 9, 10, 11, -1, 12, 13, 14, 15, -1, 16, 17, 18, 19, -1, 20, 21, 22, 23, -1
            ]
            creaseAngle 1.5
          }
        }
      ]
      name "wall#2"
      model "box"
      boundingObject Box {
        size 0.01 10 0.1
      }
    }
    Solid {
      translation 0 5.005 0.05
      children [
        Shape {
          appearance PBRAppearance {
            baseColorMap ImageTexture {
              url [
                "https://raw.githubusercontent.com/cyberbotics/webots/R2023a/projects/appearances/protos/textures/brushed_aluminium/brushed_aluminium_base_color.jpg"
              ]
            }
            roughnessMap ImageTexture {
              url [
                "https://raw.githubusercontent.com/cyberbotics/webots/R2023a/projects/appearances/protos/textures/brushed_aluminium/brushed_aluminium_roughness.jpg"
              ]
            }
            normalMap ImageTexture {
              url [
                "https://raw.githubusercontent.com/cyberbotics/webots/R2023a/projects/appearances/protos/textures/brushed_aluminium/brushed_aluminium_normal.jpg"
              ]
            }
          }
          geometry IndexedFaceSet {
            coord Coordinate {
              point [
                -5.01 0.005 0.05
                5.01 0.005 0.05
                5.01 0.005 -0.05
                -5.01 0.005 -0.05
                -5.01 -0.005 -0.05
                5.01 -0.005 -0.05
                5.01 -0.005 0.05
                -5.01 -0.005 0.05
                -5.01 -0.005 0.05
                5.01 -0.005 0.05
                5.01 0.005 0.05
                -5.01 0.005 0.05
                5.01 -0.005 -0.05
                -5.01 -0.005 -0.05
                -5.01 0.005 -0.05
                5.01 0.005 -0.05
                -5.01 -0.005 -0.05
                -5.01 -0.005 0.05
                -5.01 0.005 0.05
                -5.01 0.005 -0.05
                5.01 -0.005 0.05
                5.01 -0.005 -0.05
                5.01 0.005 -0.05
                5.01 0.005 0.05
              ]
            }
            texCoord TextureCoordinate {
              point [
                1 0.009980039920159682
                0 0.009980039920159682
                0 0
                1 0
                0 0
                1 0
                1 0.009980039920159682
                0 0.009980039920159682
                0 1
                0 0
                0.0009980039920159682 0
                0.0009980039920159682 1
                0 1
                0 0
                0.0009980039920159682 0
                0.0009980039920159682 1
                0.0009980039920159682 0
                0.0009980039920159682 0.009980039920159682
                0 0.009980039920159682
                0 0
                0 0.009980039920159682
                0 0
                0.0009980039920159682 0
                0.0009980039920159682 0.009980039920159682
              ]
            }
            coordIndex [
              0, 1, 2, 3, -1, 4, 5, 6, 7, -1, 8, 9, 10, 11, -1, 12, 13, 14, 15, -1, 16, 17, 18, 19, -1, 20, 21, 22, 23, -1
            ]
            creaseAngle 1.5
          }
        }
      ]
      name "wall#3"
      model "box"
      boundingObject Box {
        size 10.02 0.01 0.1
      }
    }
    Solid {
      translation 0 -5.005 0.05
      children [
        Shape {
          appearance PBRAppearance {
            baseColorMap ImageTexture {
              url [
                "https://raw.githubusercontent.com/cyberbotics/webots/R2023a/projects/appearances/protos/textures/brushed_aluminium/brushed_aluminium_base_color.jpg"
              ]
            }
            roughnessMap ImageTexture {
              url [
                "https://raw.githubusercontent.com/cyberbotics/webots/R2023a/projects/appearances/protos/textures/brushed_aluminium/brushed_aluminium_roughness.jpg"
              ]
            }
            normalMap ImageTexture {
              url [
                "https://raw.githubusercontent.com/cyberbotics/webots/R2023a/projects/appearances/protos/textures/brushed_aluminium/brushed_aluminium_normal.jpg"
              ]
            }
          }
          geometry IndexedFaceSet {
            coord Coordinate {
              point [
                -5.01 0.005 0.05
                5.01 0.005 0.05
                5.01 0.005 -0.05
                -5.01 0.005 -0.05
                -5.01 -0.005 -0.05
                5.01 -0.005 -0.05
                5.01 -0.005 0.05
                -5.01 -0.005 0.05
                -5.01 -0.005 0.05
                5.01 -0.005 0.05
                5.01 0.005 0.05
                -5.01 0.005 0.05
                5.01 -0.005 -0.05
                -5.01 -0.005 -0.05
                -5.01 0.005 -0.05
                5.01 0.005 -0.05
                -5.01 -0.005 -0.05
                -5.01 -0.005 0.05
                -5.01 0.005 0.05
                -5.01 0.005 -0.05
                5.01 -0.005 0.05
                5.01 -0.005 -0.05
                5.01 0.005 -0.05
                5.01 0.005 0.05
              ]
            }
            texCoord TextureCoordinate {
              point [
                1 0.009980039920159682
                0 0.009980039920159682
                0 0
                1 0
                0 0
                1 0
                1 0.009980039920159682
                0 0.009980039920159682
                0 1
                0 0
                0.0009980039920159682 0
                0.0009980039920159682 1
                0 1
                0 0
                0.0009980039920159682 0
                0.0009980039920159682 1
                0.0009980039920159682 0
                0.0009980039920159682 0.009980039920159682
                0 0.009980039920159682
                0 0
                0 0.009980039920159682
                0 0
                0.0009980039920159682 0
                0.0009980039920159682 0.009980039920159682
              ]
            }
            coordIndex [
              0, 1, 2, 3, -1, 4, 5, 6, 7, -1, 8, 9, 10, 11, -1, 12, 13, 14, 15, -1, 16, 17, 18, 19, -1, 20, 21, 22, 23, -1
            ]
            creaseAngle 1.5
          }
        }
      ]
      name "wall#4"
      model "box"
      boundingObject Box {
        size 10.02 0.01 0.1
      }
    }
  ]
  name "rectangle arena"
  model "rectangle arena"
}
Robot {
  translation 0.370854 0.67 -1.47926
  children [
    Camera {
    }
    E-puck {
    }
  ]
  name "robot(1)"
}
Transform {
  translation 1.29 0 -3.61
  children [
    Solid {
      translation 0 1.57 -6.24705e-06
      rotation 1 0 0 -1.5708003061004252
      children [
        SpotLight {
          attenuation 0 0 1
          beamWidth 0.7
          color 0.666667 0 0
          cutOffAngle 0.78538
          direction 44 -77 -9
          intensity 5
          location 0 3.1 2
        }
        Shape {
          appearance PBRAppearance {
          }
          geometry Cylinder {
            height 3.1
            radius 0.11
          }
        }
      ]
      name "poste"
      boundingObject Cylinder {
        height 3.1
        radius 0.11
      }
      physics Physics {
        mass 2
      }
      locked TRUE
    }
    Solid {
      translation 0 0.23 2.34563e-07
      rotation 1 0 0 -1.5707953071795862
      children [
        Shape {
          appearance PBRAppearance {
          }
          geometry Cylinder {
            height 0.1
            radius 0.5
          }
        }
      ]
      name "base"
      boundingObject Cylinder {
        height 0.1
        radius 0.5
      }
      physics Physics {
        mass 5
      }
      locked TRUE
    }
  ]
}
E-puck {
  translation 0.930725 0.454743 -0.734382
  rotation -1 0 0 1.3089953071795861
  controller "epuck_go_forward"
}
WoodenBox {
  translation -0.437681 0.59 -0.522471
  mass 2
}
WoodenBox {
  translation 2.18 0.59 -0.37
  name "wooden box(1)"
  mass 2
}
WoodenBox {
  translation 2.95 0.59 -1.73
  name "wooden box(2)"
  mass 2
}
Robot {
  translation 0 0.96 0
  children [
    SliderJoint {
      jointParameters JointParameters {
      }
      endPoint Solid {
        children [
          HingeJoint {
            endPoint Solid {
              children [
                Camera {
                }
              ]
            }
          }
        ]
      }
    }
    Camera {
      name "CAM"
    }
  ]
  controller "<none>"
  controllerArgs [
    "wb_camera_enable"
  ]
  supervisor TRUE
}
DEF BB-8 BB-8 {
  translation 0.328897 -0.0409758 1.1202
  rotation -0.907279407026152 0.28834181592323965 0.3061095796873445 1.73368459419624
  controller "sumo_supervisor"
}
Solid {
  physics Physics {
  }
}
Robot {
  name "supervisor"
  controller ""
  supervisor TRUE
}
DEF BALL Solid {
  translation 0.593641 0.890233 0.06435
  rotation -0.36201175376949435 0.7583959747851028 -0.5420175601975353 -1.8710081880137999
  children [
    Shape {
      appearance DEF SPHERE_COLOR PBRAppearance {
        baseColor 1 0 0
      }
      geometry DEF SPHERE_GEOMETRY Sphere {
        radius 0.2
      }
    }
  ]
  name "solid(1)"
  boundingObject USE SPHERE_GEOMETRY
  physics Physics {
    density -1
    mass 0.1
  }
}
Nao {
  translation -2.002708574526623 0.33232506542679424 0.9312893796532576
  rotation -0.6015132101407612 0.5638542360040532 0.5659065811301736 2.0556899516349554
  controller "nao_by_ai"
  supervisor TRUE
  cameraFocus Focus {
  }
}
Pedestrian {
  translation -2.79224 1.54 3.7
  rotation -0.9351134888498739 0.25056313098704747 0.2505611309860019 1.63784
}
Solid {
  translation 7.83 8.87 9.26
  children [
    PointLight {
      attenuation 0 0 1
      intensity 50
      location 0 0.3 0
      castShadows TRUE
    }
    Shape {
      geometry Sphere {
      }
    }
  ]
  name "sun"
}
